<mujoco model="astribot_gripper_left">

<!--    夹爪基座-->
    <body name="astribot_gripper_right_base" pos="0.0 0.0 .0">
<!--      <geom class="Widget" rgba="0 1 0 0.1" pos="0 0 0.1" euler="0 0 0" type="box" size="0.075 0.02 0.05"  />-->
      <geom class="Widget" rgba="0 1 0 0.1" pos="0 0 0.025" euler="0 0 0" type="capsule" size="0.035 0.075"  />
      <geom type="mesh" rgba="0.2 0.2 0.2 1" mesh="gripper_base_link"/>
      <geom name="astribot_gripper_right_base_geom" type="box" size=" 0.03 0.0135 0.01" pos="0.00 0 0.08" rgba="0.5 0.2 0.2 1" friction="1.5" priority="3" />

      <inertial pos="0.0 0.0 0.04"  quat="0.0 0.0 -0.0 1.0" mass="0.4" diaginertia="0.001 0.001 0.001"/>
<!--        左手指平行连杆1-->
      <body name="astribot_gripper_right_Link_L1" pos="0.013001 0 0.0537">
          <joint class="gripper_size1" name="astribot_gripper_right_joint_L1" pos="0 0 0" axis="0 -1 0" range="0 1.14 " />
          <geom name="astribot_gripper_right_geom_L1" type="mesh" rgba="0.898039 0.917647 0.929412 1" mesh="gripper_L1_Link"/>
        <inertial pos="0.0 0.0 0.02"  quat="0.0 0.0 -0.0 1.0" mass="0.03" diaginertia="0.001 0.001 0.001"/>
          <body name="astribot_gripper_right_Link_L11" pos="0.036 0 0.031749" euler="0 -0.03 0">
              <joint class="gripper_size1" name="astribot_gripper_right_joint_L11" pos="0 0 0" axis="0 1 0" range="-3.14 3.14" />
              <inertial pos="0.0 0.0 0.02"  quat="0.0 0.0 -0.0 1.0" mass="0.067" diaginertia="0.001 0.001 0.001"/>
              <geom name="astribot_gripper_right_geom_L11" type="mesh" rgba="0.898039 0.917647 0.929412 1" mesh="gripper_L11_Link"/>
              <geom name="astribot_gripper_right_geom_L112" type="box" size=" 0.004 0.0135 0.03" pos="-0.003 0 0.036" rgba="0.5 0.2 0.2 1" friction="1.8 1.2 1.2   " priority="1"/>

<!--              <body name="right_gripper_L11_anchor" pos="0.02 0 0.0"/>-->

          </body>
      </body>
<!--        左手指平行连杆2-->
      <body name="astribot_gripper_right_Link_L2" pos=".033 0 0.0537">
          <joint class="gripper_size1" name="astribot_gripper_right_joint_L2" pos="0 0 0" axis="0 1 0" range="-3.14 3.14" />
          <geom name="astribot_gripper_right_geom_L2" type="mesh" rgba="0.898039 0.917647 0.929412 1" mesh="gripper_L2_Link"/>
          <inertial pos="0.0 0.0 0.02"  quat="0.0 0.0 -0.0 1.0" mass="0.03" diaginertia="0.001 0.001 0.001"/>
<!--          <body name="right_gripper_L2_anchor" pos="0.036 0 0.031749"/>-->
      </body>

<!--        右手指平行连杆1-->
      <body name="astribot_gripper_right_Link_R1" pos="-0.013001 0 0.0537">
          <joint class="gripper_size1" name="astribot_gripper_right_joint_R1" pos="0 0 0" axis="0 1 0" range="0 1.14 " />
          <geom name="astribot_gripper_right_geom_R1" type="mesh" rgba="0.898039 0.917647 0.929412 1" mesh="gripper_R1_Link"/>

          <inertial pos="0.0 0.0 0.02"  quat="0.0 0.0 -0.0 1.0" mass="0.03" diaginertia="0.001 0.001 0.001"/>
          <body name="astribot_gripper_right_Link_R11" pos="-0.036 0 0.031749" euler="0 0.03 0">
              <joint class="gripper_size1" name="astribot_gripper_right_joint_R11" pos="0 0 0" axis="0 1 0" range="-3.14 3.14" />

              <inertial pos="0.0 0.0 0.02"  quat="0.0 0.0 -0.0 1.0" mass="0.067" diaginertia="0.001 0.001 0.001"/>
              <geom name="astribot_gripper_right_geom_R11" type="mesh" rgba="0.898039 0.917647 0.929412 1" mesh="gripper_R11_Link"/>
              <geom name="astribot_gripper_right_geom_R112" type="box" size=" 0.004 0.0135 0.03" pos="0.003 0 0.036" rgba="0.5 0.2 0.2 1" friction="1.5" priority="3" />
          </body>
      </body>
<!--        右手指平行连杆2-->
      <body name="astribot_gripper_right_Link_R2" pos="-0.033 0 0.0537">
          <joint class="gripper_size1" name="astribot_gripper_right_joint_R2" pos="0 0 0" axis="0 1 0" range="-3.14 3.14" />
          <geom name="astribot_gripper_right_geom_R2" type="mesh" rgba="0.898039 0.917647 0.929412 1" mesh="gripper_R2_Link"/>
         <inertial pos="0.0 0.0 0.02"  quat="0.0 0.0 -0.0 1.0" mass="0.03" diaginertia="0.001 0.001 0.001"/>
      </body>
    </body>
</mujoco>

